<?xml version="1.0" encoding="UTF-8"?>
<testng-results skipped="0" failed="1" ignored="0" total="1" passed="0">
  <reporter-output>
  </reporter-output>
  <suite name="Suite" duration-ms="7203" started-at="2020-03-04T20:32:42 IST" finished-at="2020-03-04T20:32:49 IST">
    <groups>
    </groups>
    <test name="Test" duration-ms="7203" started-at="2020-03-04T20:32:42 IST" finished-at="2020-03-04T20:32:49 IST">
      <class name="autodemo.resources.MyFirstTest">
        <test-method status="FAIL" signature="MyTest()[pri:0, instance:autodemo.resources.MyFirstTest@273e7444]" name="MyTest" duration-ms="5977" started-at="2020-03-04T20:32:42 IST" finished-at="2020-03-04T20:32:48 IST">
          <exception class="java.lang.AssertionError">
            <message>
              <![CDATA[expected [true] but found [false]]]>
            </message>
            <full-stacktrace>
              <![CDATA[java.lang.AssertionError: expected [true] but found [false]
at org.testng.Assert.fail(Assert.java:97)
at org.testng.Assert.failNotEquals(Assert.java:969)
at org.testng.Assert.assertTrue(Assert.java:43)
at org.testng.Assert.assertTrue(Assert.java:53)
at autodemo.resources.MyFirstTest.MyTest(MyFirstTest.java:16)
at sun.reflect.NativeMethodAccessorImpl.invoke0(Native Method)
at sun.reflect.NativeMethodAccessorImpl.invoke(Unknown Source)
at sun.reflect.DelegatingMethodAccessorImpl.invoke(Unknown Source)
at java.lang.reflect.Method.invoke(Unknown Source)
at org.testng.internal.MethodInvocationHelper.invokeMethod(MethodInvocationHelper.java:134)
at org.testng.internal.TestInvoker.invokeMethod(TestInvoker.java:597)
at org.testng.internal.TestInvoker.invokeTestMethod(TestInvoker.java:173)
at org.testng.internal.MethodRunner.runInSequence(MethodRunner.java:46)
at org.testng.internal.TestInvoker$MethodInvocationAgent.invoke(TestInvoker.java:816)
at org.testng.internal.TestInvoker.invokeTestMethods(TestInvoker.java:146)
at org.testng.internal.TestMethodWorker.invokeTestMethods(TestMethodWorker.java:146)
at org.testng.internal.TestMethodWorker.run(TestMethodWorker.java:128)
at java.util.ArrayList.forEach(Unknown Source)
at org.testng.TestRunner.privateRun(TestRunner.java:766)
at org.testng.TestRunner.run(TestRunner.java:587)
at org.testng.SuiteRunner.runTest(SuiteRunner.java:384)
at org.testng.SuiteRunner.runSequentially(SuiteRunner.java:378)
at org.testng.SuiteRunner.privateRun(SuiteRunner.java:337)
at org.testng.SuiteRunner.run(SuiteRunner.java:286)
at org.testng.SuiteRunnerWorker.runSuite(SuiteRunnerWorker.java:53)
at org.testng.SuiteRunnerWorker.run(SuiteRunnerWorker.java:96)
at org.testng.TestNG.runSuitesSequentially(TestNG.java:1187)
at org.testng.TestNG.runSuitesLocally(TestNG.java:1109)
at org.testng.TestNG.runSuites(TestNG.java:1039)
at org.testng.TestNG.run(TestNG.java:1007)
at org.apache.maven.surefire.testng.TestNGExecutor.run(TestNGExecutor.java:283)
at org.apache.maven.surefire.testng.TestNGXmlTestSuite.execute(TestNGXmlTestSuite.java:75)
at org.apache.maven.surefire.testng.TestNGProvider.invoke(TestNGProvider.java:120)
at org.apache.maven.surefire.booter.ForkedBooter.runSuitesInProcess(ForkedBooter.java:377)
at org.apache.maven.surefire.booter.ForkedBooter.execute(ForkedBooter.java:138)
at org.apache.maven.surefire.booter.ForkedBooter.run(ForkedBooter.java:465)
at org.apache.maven.surefire.booter.ForkedBooter.main(ForkedBooter.java:451)
]]>
            </full-stacktrace>
          </exception> <!-- java.lang.AssertionError -->
          <reporter-output>
          </reporter-output>
        </test-method> <!-- MyTest -->
        <test-method status="PASS" signature="teardown()[pri:0, instance:autodemo.resources.MyFirstTest@273e7444]" name="teardown" is-config="true" duration-ms="1173" started-at="2020-03-04T20:32:48 IST" finished-at="2020-03-04T20:32:49 IST">
          <reporter-output>
          </reporter-output>
        </test-method> <!-- teardown -->
      </class> <!-- autodemo.resources.MyFirstTest -->
    </test> <!-- Test -->
  </suite> <!-- Suite -->
</testng-results>
